<?xml version='1.0'?>

<robot name="tablebot" xmlns:xacro="http://www.ros.org/wiki/xacro">



  <!-- xacro:include filename="$(find tbot_description)/urdf/tbot.gazebo" / -->
  <!--<xacro:include filename="$(find tbot_description)/urdf/materials.xacro" / -->
	  <!-- <xacro:include filename="$(find tbot_description)/urdf/macros.xacro" / -->


  <link name='chassis'>
    <pose>0 0 0.1 0 0 0</pose>

    <inertial>
      <mass value="10.0"/>
      <origin xyz="0.0 0 0.1" rpy=" 0 0 0"/>
      <inertia
          ixx="0.5" ixy="0" ixz="0"
          iyy="1.0" iyz="0"
          izz="0.1"
      />
    </inertial>

    <collision name='collision'>
      <geometry>
        <box size=".4 .2 .1"/>
      </geometry>
    </collision>

    <visual name='chassis_visual'>
      <origin xyz="0 0 0" rpy=" 0 0 0"/>
      <geometry>
        <box size=".4 .2 .1"/>
      </geometry>
    </visual>


    <collision name='front_caster_collision'>
      <origin xyz="-0.15 0 -0.05" rpy=" 0 0 0"/>
      <geometry>
        <!--sphere radius="0.05"/-->
        <sphere radius="0.048"/>
      </geometry>
      <surface>
        <friction>
          <ode>
            <mu>0</mu>
            <mu2>0</mu2>
            <slip1>1.0</slip1>
            <slip2>1.0</slip2>
          </ode>
        </friction>
      </surface>
    </collision>

    <visual name='front_caster_visual'>
      <origin xyz="-0.15 0 -0.05" rpy=" 0 0 0"/>
      <geometry>
        <!--sphere radius="0.05"/-->
        <sphere radius="0.048"/>
      </geometry>
    </visual>

    <collision name='back_caster_collision'>
      <origin xyz="0.15 0 -0.05" rpy=" 0 0 0"/>
      <geometry>
        <!--sphere radius="0.05"/-->
        <sphere radius="0.048"/>
      </geometry>
      <surface>
        <friction>
          <ode>
            <mu>0</mu>
            <mu2>0</mu2>
            <slip1>1.0</slip1>
            <slip2>1.0</slip2>
          </ode>
        </friction>
      </surface>
    </collision>

    <visual name='back_caster_visual'>
      <origin xyz="0.15 0 -0.05" rpy=" 0 0 0"/>
      <geometry>
        <!--sphere radius="0.05"/-->
        <sphere radius="0.048"/>
      </geometry>
    </visual>
  </link>


  <link name="left_wheel">
    <!--origin xyz="0.1 0.13 0.1" rpy="0 1.5707 1.5707"/-->
    <collision name="collision">
      <origin xyz="0 0 0" rpy="0 1.5707 1.5707"/>
      <geometry>
        <cylinder radius="0.1" length="0.05"/>
      </geometry>
    </collision>

    <visual name="left_wheel_visual">
      <origin xyz="0 0 0" rpy="0 1.5707 1.5707"/>
      <geometry>
        <cylinder radius="0.1" length="0.05"/>
      </geometry>
    </visual>
    <inertial>
      <origin xyz="0 0 0" rpy="0 1.5707 1.5707"/>
      <mass value="5"/>
      <cylinder_inertia m="5" r="0.1" h="0.05"/>
      <inertia
        ixx="1.0" ixy="0.0" ixz="0.0"
        iyy="1.0" iyz="0.0"
        izz="1.0"/>
    </inertial>
  </link>

  <link name="right_wheel">
    <!--origin xyz="0.1 -0.13 0.1" rpy="0 1.5707 1.5707"/-->
    <collision name="collision">
      <origin xyz="0 0 0" rpy="0 1.5707 1.5707"/>
      <geometry>
        <cylinder radius="0.1" length="0.05"/>
      </geometry>
    </collision>

    <visual name="right_wheel_visual">
      <origin xyz="0 0 0" rpy="0 1.5707 1.5707"/>
      <geometry>
        <cylinder radius="0.1" length="0.05"/>
      </geometry>
    </visual>
    <inertial>
      <origin xyz="0 0 0" rpy="0 1.5707 1.5707"/>
      <mass value="5"/>
      <cylinder_inertia m="5" r="0.1" h="0.05"/>
      <inertia
        ixx="1.0" ixy="0.0" ixz="0.0"
        iyy="1.0" iyz="0.0"
        izz="1.0"/>
    </inertial>
  </link>


  <joint type="continuous" name="left_wheel_hinge">
    <origin xyz="0.0 0.15 0" rpy="0 0 0"/>
    <child link="left_wheel"/>
    <parent link="chassis"/>
    <axis xyz="0 1 0" rpy="0 0 0"/>
    <limit effort="100" velocity="100"/>
    <joint_properties damping="0.0" friction="0.0"/>
  </joint>

  <joint type="continuous" name="right_wheel_hinge">
    <origin xyz="0.0 -0.15 0" rpy="0 0 0"/>
    <child link="right_wheel"/>
    <parent link="chassis"/>
    <axis xyz="0 1 0" rpy="0 0 0"/>
    <limit effort="100" velocity="100"/>
    <joint_properties damping="0.0" friction="0.0"/>
  </joint>

  <joint name="sonar_joint" type="fixed">
	  <axis xyz="0 1 0" />
	  <origin xyz=".25 0 0" rpy="0 0.7854 0" />
	  <parent link="chassis" />
	  <child link="sonar" />
  </joint>

<!--Sonar link -->
<link name="sonar">
    <pose>0 0 0 0 0 0</pose>

    <inertial>
      <mass value="1.0"/>
      <origin xyz="0 0 0" rpy="0 0 0"/>
      <inertia
          ixx="0.5" ixy="0" ixz="0"
          iyy="1.0" iyz="0"
          izz="0.1"
      />
    </inertial>

	<!--
    <collision name="sonar_collision">
      <geometry>
        <box size=".1 .1 .1"/>
      </geometry>
    </collision>
	-->

    <visual name="sonar_visual">
      <origin xyz="0 0 0" rpy=" 0 0 0"/>
      <geometry>
        <box size=".05 .1 .1"/>
      </geometry>
    </visual>
</link>

<!-- Gazebo chassis color -->
<gazebo reference="chassis">
  <material>Gazebo/Orange</material>
</gazebo>


<!-- Diff Drive Gazebo Plugin -->
<gazebo>
	<plugin name="differential_drive_controller" filename="libgazebo_ros_diff_drive.so">
	  <legacyMode>false</legacyMode>
	  <alwaysOn>true</alwaysOn>
	  <updateRate>20</updateRate>
	  <leftJoint>left_wheel_hinge</leftJoint>
	  <rightJoint>right_wheel_hinge</rightJoint>
	  <wheelSeparation>0.3</wheelSeparation>
	  <wheelDiameter>0.2</wheelDiameter>
	  <torque>20</torque>
	  <commandTopic>cmd_vel</commandTopic>
	  <odometryTopic>odom</odometryTopic>
	  <odometryFrame>odom</odometryFrame>
	  <robotBaseFrame>chassis</robotBaseFrame>
	</plugin>
</gazebo>


<!-- Sonar Gazebo Plugin -->
<gazebo reference="sonar">
    <material>Gazebo/Green</material>
    <sensor type="ray" name="sonar_sensor">
        <pose>0 0 0 0 0 0</pose> 
        <update_rate>5</update_rate>
        <ray>
            <scan>
                <horizontal>
                    <samples>5</samples>
                    <resolution>1.0</resolution>
                    <min_angle>-0.25</min_angle>
                    <max_angle>0.25</max_angle>
                </horizontal>
                <vertical>
                    <samples>5</samples>
                    <resolution>1</resolution>
                    <min_angle>-0.25</min_angle>
                    <max_angle>0.25</max_angle>
                </vertical>
            </scan>
            <range>
                <min>0.01</min>
                <max>0.75</max>
                <resolution>0.01</resolution>
            </range>
        </ray>

        <plugin filename="libgazebo_ros_range.so" name="gazebo_ros_range">
            <!--<gaussianNoise>0.005</gaussianNoise> -->
            <gaussianNoise>0.0</gaussianNoise>
            <alwaysOn>true</alwaysOn>
            <updateRate>5</updateRate>
            <topicName>sonar1</topicName>
            <frameName>sonar</frameName>
            <fov>0.5</fov>
            <radiation>ultrasound</radiation>
        </plugin>
    </sensor>
</gazebo>


</robot>


